Workbook

Sheet Lisez-moi
B1: Inventaire des données pour instancier MAELIA en Guadeloupe
B2: Généré le 14/10/2026 à partir des tables MOSAICA (année 2017, scénario RESTIT) et de la documentation MAELIA.
B4: L'échelle
A5: 0 | B5: Absente et difficile à obtenir | C5: Ni dans MOSAICA ni dans un référentiel : expérimentation, calibration ou enquête lourde.
A6: 1 | B6: Absente mais accessible | C6: Pas dans MOSAICA, mais publiée ou récupérable vite : littérature, base publique, dire d'expert.
A7: 2 | B7: Disponible, à retravailler | C7: Une valeur existe : proxy, valeur par famille, autre unité ou définition, niveau discutable.
A8: 3 | B8: Disponible et utilisable | C8: Dans les tables de MOSAICA, à la bonne maille : une simple mise en forme suffit.
A9: – | B9: Sans objet | C9: Le paramètre ne concerne pas cette culture (pas d'irrigation, pas de travail du sol, prairie simulée par HerbSim, jachère sans ITK).
B11: Les feuilles
B12: Synthèse | C12: Score moyen par famille de cultures et par thème, et les verrous qui ne tiennent pas aux données.
B13: Cultures | C13: 75 cultures fines de MOSAICA × 50 paramètres MAELIA. Survoler un en-tête de colonne affiche le sens du paramètre et la règle de notation.
B14: Paramètres | C14: Le dictionnaire des colonnes : ce que MOSAICA a, comment la note est donnée, où chercher, et la surface concernée par chaque manque.
B15: Autres données | C15: 48 jeux de données hors cultures (climat, sols, parcellaire, exploitations, hydrologie…), avec leurs sources et leurs liens.
B17: Comment les notes sont données
B18: Notes calculées | C18: Quand la donnée se lit dans les tables de MOSAICA (rendement, opérations, temps de travail, doses, prix, aides, charges), la note est calculée culture par culture. Elle est plafonnée à 2 quand la valeur est un proxy ou que son niveau est discuté.
B19: Notes appréciées | C19: Quand la donnée manque (phénologie, Kc, réponse à l'eau, besoins en azote, calendrier), la note dit seulement si une référence publiée existe pour la plante : 1 si oui, 0 sinon. C'est une appréciation à faire valider par les agronomes ; les pistes de sources n'ont pas été vérifiées une à une.
B20: Variantes d'une même plante | C20: Les paramètres d'espèce sont communs à toutes les variantes d'une plante (les 18 cannes à sucre, les 4 bananes) : seuls l'ITK, le rendement et l'économie les distinguent.
B21: Surface 2017 | C21: Surface observée, ventilée sur les cultures fines par les règles GAMS d'attribution des ITK. Elle sert à pondérer : un manque sur la canne pèse plus qu'un manque sur le melon.
B22: Corriger une note | C22: Les notes se modifient dans la feuille Cultures (liste déroulante) ; couleurs, moyennes et Synthèse suivent. Relancer le script écrase ces corrections : pour les garder, les reporter dans le script.
B24: Sources MAELIA et versions
B25: Guide de l'utilisateur | C25: Version d'août 2026 : structure des fichiers, application ITK. Tables parfois tronquées.
B26: Note de 2022 | C26: Note d'accompagnement à la préparation des données d'entrée : champs obligatoires des sols, couples de règles de déclenchement.
B27: Formation de septembre 2026 | C27: Supports, grille d'enquête ITK (version 1.4.22) et deux jeux d'exemple : terrainTest et le jeu du TD, simulé avec MAELIA 1.4.31.
B28: Quand les sources divergent | C28: Le jeu 1.4.31 fait foi, parce qu'il a tourné : dossier parametres/, lignes d'ITK renommées, prairies simulées avec l'azote, économie facultative. Les points douteux sont listés en bas de la feuille Synthèse.
B30: Liens utiles
B31: Documentation MAELIA | C31: https://maelia.pages-forge.inrae.fr/documentation
B32: Documentation MAELIA — données d'entrée | C32: https://maelia.pages-forge.inrae.fr/documentation/04-donnees_entree.html
B33: Application ITK (compte : Renaud Misslin, MAELAB) | C33: https://analytics.huma-num.fr/Renaud.Misslin/maelia_itk/
B34: Forum MAELIA | C34: https://forum-maelia.discourse.group/
B35: Site MAELIA | C35: https://www.maelia-iam.fr/
B37: Régénérer | C37: .venv/Scripts/python clement/maelia/build_inventaire_donnees_maelia.py
C38: Pour aller plus loin : docs/maelia/README.md, crop-parameters.md et coupling-todo.md dans le dépôt MOSAICA.

Sheet Synthèse
A1: Synthèse : où en sont les données pour MAELIA en Guadeloupe
A2: Moyenne des notes (0 à 3) ; les cellules sans objet ne comptent pas. Tout est recalculé depuis les feuilles Cultures et Autres données.
A4: Par famille de cultures
A5: Famille | B5: Variantes | C5: Surface 2017 (ha) | D5: Espèce : eau, phéno | E5: Espèce : N et C | F5: ITK | G5: Fertilisation | H5: Économie | I5: Score global
A6: Canne à sucre et canne fibre | B6: =COUNTIF(Cultures!$A$5:$A$79,$A6) -> 28 | C6: =SUMIF(Cultures!$A$5:$A$79,$A6,Cultures!$D$5:$D$79) -> 12812.93 | D6: =IFERROR(AVERAGEIFS(Cultures!$BG$5:$BG$79,Cultures!$A$5:$A$79,$A6),"–") -> 1.2433036 | E6: =IFERROR(AVERAGEIFS(Cultures!$BH$5:$BH$79,Cultures!$A$5:$A$79,$A6),"–") -> 1.2142857 | F6: =IFERROR(AVERAGEIFS(Cultures!$BI$5:$BI$79,Cultures!$A$5:$A$79,$A6),"–") -> 1.6996753 | G6: =IFERROR(AVERAGEIFS(Cultures!$BJ$5:$BJ$79,Cultures!$A$5:$A$79,$A6),"–") -> 2 | H6: =IFERROR(AVERAGEIFS(Cultures!$BK$5:$BK$79,Cultures!$A$5:$A$79,$A6),"–") -> 1.5285714 | I6: =IFERROR(AVERAGEIFS(Cultures!$BL$5:$BL$79,Cultures!$A$5:$A$79,$A6),"–") -> 1.3828869
A7: Banane dessert | B7: =COUNTIF(Cultures!$A$5:$A$79,$A7) -> 4 | C7: =SUMIF(Cultures!$A$5:$A$79,$A7,Cultures!$D$5:$D$79) -> 1920.8 | D7: =IFERROR(AVERAGEIFS(Cultures!$BG$5:$BG$79,Cultures!$A$5:$A$79,$A7),"–") -> 1.25 | E7: =IFERROR(AVERAGEIFS(Cultures!$BH$5:$BH$79,Cultures!$A$5:$A$79,$A7),"–") -> 1.2884615 | F7: =IFERROR(AVERAGEIFS(Cultures!$BI$5:$BI$79,Cultures!$A$5:$A$79,$A7),"–") -> 1.3159091 | G7: =IFERROR(AVERAGEIFS(Cultures!$BJ$5:$BJ$79,Cultures!$A$5:$A$79,$A7),"–") -> 2 | H7: =IFERROR(AVERAGEIFS(Cultures!$BK$5:$BK$79,Cultures!$A$5:$A$79,$A7),"–") -> 1.6 | I7: =IFERROR(AVERAGEIFS(Cultures!$BL$5:$BL$79,Cultures!$A$5:$A$79,$A7),"–") -> 1.3458603
A8: Plantain | B8: =COUNTIF(Cultures!$A$5:$A$79,$A8) -> 2 | C8: =SUMIF(Cultures!$A$5:$A$79,$A8,Cultures!$D$5:$D$79) -> 147.21 | D8: =IFERROR(AVERAGEIFS(Cultures!$BG$5:$BG$79,Cultures!$A$5:$A$79,$A8),"–") -> 1.25 | E8: =IFERROR(AVERAGEIFS(Cultures!$BH$5:$BH$79,Cultures!$A$5:$A$79,$A8),"–") -> 1.3846154 | F8: =IFERROR(AVERAGEIFS(Cultures!$BI$5:$BI$79,Cultures!$A$5:$A$79,$A8),"–") -> 1.4272727 | G8: =IFERROR(AVERAGEIFS(Cultures!$BJ$5:$BJ$79,Cultures!$A$5:$A$79,$A8),"–") -> 2 | H8: =IFERROR(AVERAGEIFS(Cultures!$BK$5:$BK$79,Cultures!$A$5:$A$79,$A8),"–") -> 1.6 | I8: =IFERROR(AVERAGEIFS(Cultures!$BL$5:$BL$79,Cultures!$A$5:$A$79,$A8),"–") -> 1.3977798
A9: Prairies | B9: =COUNTIF(Cultures!$A$5:$A$79,$A9) -> 2 | C9: =SUMIF(Cultures!$A$5:$A$79,$A9,Cultures!$D$5:$D$79) -> 6109.43 | D9: =IFERROR(AVERAGEIFS(Cultures!$BG$5:$BG$79,Cultures!$A$5:$A$79,$A9),"–") -> 0 | E9: =IFERROR(AVERAGEIFS(Cultures!$BH$5:$BH$79,Cultures!$A$5:$A$79,$A9),"–") -> – | F9: =IFERROR(AVERAGEIFS(Cultures!$BI$5:$BI$79,Cultures!$A$5:$A$79,$A9),"–") -> 0.91964286 | G9: =IFERROR(AVERAGEIFS(Cultures!$BJ$5:$BJ$79,Cultures!$A$5:$A$79,$A9),"–") -> 1.5 | H9: =IFERROR(AVERAGEIFS(Cultures!$BK$5:$BK$79,Cultures!$A$5:$A$79,$A9),"–") -> 1.6 | I9: =IFERROR(AVERAGEIFS(Cultures!$BL$5:$BL$79,Cultures!$A$5:$A$79,$A9),"–") -> 1.125
A10: Maraîchage (dont tomate) | B10: =COUNTIF(Cultures!$A$5:$A$79,$A10) -> 30 | C10: =SUMIF(Cultures!$A$5:$A$79,$A10,Cultures!$D$5:$D$79) -> 1086.97 | D10: =IFERROR(AVERAGEIFS(Cultures!$BG$5:$BG$79,Cultures!$A$5:$A$79,$A10),"–") -> 0.82708333 | E10: =IFERROR(AVERAGEIFS(Cultures!$BH$5:$BH$79,Cultures!$A$5:$A$79,$A10),"–") -> 1.1717949 | F10: =IFERROR(AVERAGEIFS(Cultures!$BI$5:$BI$79,Cultures!$A$5:$A$79,$A10),"–") -> 1.3381145 | G10: =IFERROR(AVERAGEIFS(Cultures!$BJ$5:$BJ$79,Cultures!$A$5:$A$79,$A10),"–") -> 1.5166667 | H10: =IFERROR(AVERAGEIFS(Cultures!$BK$5:$BK$79,Cultures!$A$5:$A$79,$A10),"–") -> 1.6 | I10: =IFERROR(AVERAGEIFS(Cultures!$BL$5:$BL$79,Cultures!$A$5:$A$79,$A10),"–") -> 1.1458325
A11: Melon | B11: =COUNTIF(Cultures!$A$5:$A$79,$A11) -> 1 | C11: =SUMIF(Cultures!$A$5:$A$79,$A11,Cultures!$D$5:$D$79) -> 189.36 | D11: =IFERROR(AVERAGEIFS(Cultures!$BG$5:$BG$79,Cultures!$A$5:$A$79,$A11),"–") -> 1.25 | E11: =IFERROR(AVERAGEIFS(Cultures!$BH$5:$BH$79,Cultures!$A$5:$A$79,$A11),"–") -> 1.3846154 | F11: =IFERROR(AVERAGEIFS(Cultures!$BI$5:$BI$79,Cultures!$A$5:$A$79,$A11),"–") -> 1.5454545 | G11: =IFERROR(AVERAGEIFS(Cultures!$BJ$5:$BJ$79,Cultures!$A$5:$A$79,$A11),"–") -> 2 | H11: =IFERROR(AVERAGEIFS(Cultures!$BK$5:$BK$79,Cultures!$A$5:$A$79,$A11),"–") -> 1.6 | I11: =IFERROR(AVERAGEIFS(Cultures!$BL$5:$BL$79,Cultures!$A$5:$A$79,$A11),"–") -> 1.4255319
A12: Igname | B12: =COUNTIF(Cultures!$A$5:$A$79,$A12) -> 2 | C12: =SUMIF(Cultures!$A$5:$A$79,$A12,Cultures!$D$5:$D$79) -> 145.42 | D12: =IFERROR(AVERAGEIFS(Cultures!$BG$5:$BG$79,Cultures!$A$5:$A$79,$A12),"–") -> 1.1875 | E12: =IFERROR(AVERAGEIFS(Cultures!$BH$5:$BH$79,Cultures!$A$5:$A$79,$A12),"–") -> 1.3076923 | F12: =IFERROR(AVERAGEIFS(Cultures!$BI$5:$BI$79,Cultures!$A$5:$A$79,$A12),"–") -> 1.5681818 | G12: =IFERROR(AVERAGEIFS(Cultures!$BJ$5:$BJ$79,Cultures!$A$5:$A$79,$A12),"–") -> 2 | H12: =IFERROR(AVERAGEIFS(Cultures!$BK$5:$BK$79,Cultures!$A$5:$A$79,$A12),"–") -> 1.6 | I12: =IFERROR(AVERAGEIFS(Cultures!$BL$5:$BL$79,Cultures!$A$5:$A$79,$A12),"–") -> 1.3869103
A13: Ananas | B13: =COUNTIF(Cultures!$A$5:$A$79,$A13) -> 2 | C13: =SUMIF(Cultures!$A$5:$A$79,$A13,Cultures!$D$5:$D$79) -> 132.67 | D13: =IFERROR(AVERAGEIFS(Cultures!$BG$5:$BG$79,Cultures!$A$5:$A$79,$A13),"–") -> 1.1875 | E13: =IFERROR(AVERAGEIFS(Cultures!$BH$5:$BH$79,Cultures!$A$5:$A$79,$A13),"–") -> 1.2307692 | F13: =IFERROR(AVERAGEIFS(Cultures!$BI$5:$BI$79,Cultures!$A$5:$A$79,$A13),"–") -> 1.9375 | G13: =IFERROR(AVERAGEIFS(Cultures!$BJ$5:$BJ$79,Cultures!$A$5:$A$79,$A13),"–") -> 2 | H13: =IFERROR(AVERAGEIFS(Cultures!$BK$5:$BK$79,Cultures!$A$5:$A$79,$A13),"–") -> 1.6 | I13: =IFERROR(AVERAGEIFS(Cultures!$BL$5:$BL$79,Cultures!$A$5:$A$79,$A13),"–") -> 1.4204545
A14: Agrumes | B14: =COUNTIF(Cultures!$A$5:$A$79,$A14) -> 1 | C14: =SUMIF(Cultures!$A$5:$A$79,$A14,Cultures!$D$5:$D$79) -> 100.84 | D14: =IFERROR(AVERAGEIFS(Cultures!$BG$5:$BG$79,Cultures!$A$5:$A$79,$A14),"–") -> 0.9375 | E14: =IFERROR(AVERAGEIFS(Cultures!$BH$5:$BH$79,Cultures!$A$5:$A$79,$A14),"–") -> 1.1538462 | F14: =IFERROR(AVERAGEIFS(Cultures!$BI$5:$BI$79,Cultures!$A$5:$A$79,$A14),"–") -> 1.5454545 | G14: =IFERROR(AVERAGEIFS(Cultures!$BJ$5:$BJ$79,Cultures!$A$5:$A$79,$A14),"–") -> 2 | H14: =IFERROR(AVERAGEIFS(Cultures!$BK$5:$BK$79,Cultures!$A$5:$A$79,$A14),"–") -> 1.6 | I14: =IFERROR(AVERAGEIFS(Cultures!$BL$5:$BL$79,Cultures!$A$5:$A$79,$A14),"–") -> 1.2553191
A15: Vergers | B15: =COUNTIF(Cultures!$A$5:$A$79,$A15) -> 2 | C15: =SUMIF(Cultures!$A$5:$A$79,$A15,Cultures!$D$5:$D$79) -> 310.89 | D15: =IFERROR(AVERAGEIFS(Cultures!$BG$5:$BG$79,Cultures!$A$5:$A$79,$A15),"–") -> 0.8125 | E15: =IFERROR(AVERAGEIFS(Cultures!$BH$5:$BH$79,Cultures!$A$5:$A$79,$A15),"–") -> 1 | F15: =IFERROR(AVERAGEIFS(Cultures!$BI$5:$BI$79,Cultures!$A$5:$A$79,$A15),"–") -> 1.5 | G15: =IFERROR(AVERAGEIFS(Cultures!$BJ$5:$BJ$79,Cultures!$A$5:$A$79,$A15),"–") -> 1.5 | H15: =IFERROR(AVERAGEIFS(Cultures!$BK$5:$BK$79,Cultures!$A$5:$A$79,$A15),"–") -> 1.6 | I15: =IFERROR(AVERAGEIFS(Cultures!$BL$5:$BL$79,Cultures!$A$5:$A$79,$A15),"–") -> 1.1382979
A16: Jachère | B16: =COUNTIF(Cultures!$A$5:$A$79,$A16) -> 1 | C16: =SUMIF(Cultures!$A$5:$A$79,$A16,Cultures!$D$5:$D$79) -> 621.47 | D16: =IFERROR(AVERAGEIFS(Cultures!$BG$5:$BG$79,Cultures!$A$5:$A$79,$A16),"–") -> – | E16: =IFERROR(AVERAGEIFS(Cultures!$BH$5:$BH$79,Cultures!$A$5:$A$79,$A16),"–") -> – | F16: =IFERROR(AVERAGEIFS(Cultures!$BI$5:$BI$79,Cultures!$A$5:$A$79,$A16),"–") -> 2 | G16: =IFERROR(AVERAGEIFS(Cultures!$BJ$5:$BJ$79,Cultures!$A$5:$A$79,$A16),"–") -> – | H16: =IFERROR(AVERAGEIFS(Cultures!$BK$5:$BK$79,Cultures!$A$5:$A$79,$A16),"–") -> 1.5 | I16: =IFERROR(AVERAGEIFS(Cultures!$BL$5:$BL$79,Cultures!$A$5:$A$79,$A16),"–") -> 1.6
A19: Par thème, hors cultures
A20: Thème | B20: Données | C20: Qualité moyenne | D20: Données à 0
A21: Climat | B21: =COUNTIF('Autres données'!$A$5:$A$52,$A21) -> 7 | C21: =IFERROR(AVERAGEIFS('Autres données'!$G$5:$G$52,'Autres données'!$A$5:$A$52,$A21),"–") -> 1.1428571 | D21: =COUNTIFS('Autres données'!$A$5:$A$52,$A21,'Autres données'!$G$5:$G$52,0) -> 0
A22: Sols | B22: =COUNTIF('Autres données'!$A$5:$A$52,$A22) -> 9 | C22: =IFERROR(AVERAGEIFS('Autres données'!$G$5:$G$52,'Autres données'!$A$5:$A$52,$A22),"–") -> 1.3333333 | D22: =COUNTIFS('Autres données'!$A$5:$A$52,$A22,'Autres données'!$G$5:$G$52,0) -> 1
A23: Parcellaire | B23: =COUNTIF('Autres données'!$A$5:$A$52,$A23) -> 5 | C23: =IFERROR(AVERAGEIFS('Autres données'!$G$5:$G$52,'Autres données'!$A$5:$A$52,$A23),"–") -> 2 | D23: =COUNTIFS('Autres données'!$A$5:$A$52,$A23,'Autres données'!$G$5:$G$52,0) -> 0
A24: Exploitations | B24: =COUNTIF('Autres données'!$A$5:$A$52,$A24) -> 5 | C24: =IFERROR(AVERAGEIFS('Autres données'!$G$5:$G$52,'Autres données'!$A$5:$A$52,$A24),"–") -> 1.4 | D24: =COUNTIFS('Autres données'!$A$5:$A$52,$A24,'Autres données'!$G$5:$G$52,0) -> 1
A25: Engrais et PRO | B25: =COUNTIF('Autres données'!$A$5:$A$52,$A25) -> 3 | C25: =IFERROR(AVERAGEIFS('Autres données'!$G$5:$G$52,'Autres données'!$A$5:$A$52,$A25),"–") -> 1.3333333 | D25: =COUNTIFS('Autres données'!$A$5:$A$52,$A25,'Autres données'!$G$5:$G$52,0) -> 0
A26: Économie | B26: =COUNTIF('Autres données'!$A$5:$A$52,$A26) -> 3 | C26: =IFERROR(AVERAGEIFS('Autres données'!$G$5:$G$52,'Autres données'!$A$5:$A$52,$A26),"–") -> 1 | D26: =COUNTIFS('Autres données'!$A$5:$A$52,$A26,'Autres données'!$G$5:$G$52,0) -> 0
A27: Validation | B27: =COUNTIF('Autres données'!$A$5:$A$52,$A27) -> 2 | C27: =IFERROR(AVERAGEIFS('Autres données'!$G$5:$G$52,'Autres données'!$A$5:$A$52,$A27),"–") -> 0.5 | D27: =COUNTIFS('Autres données'!$A$5:$A$52,$A27,'Autres données'!$G$5:$G$52,0) -> 1
A28: Référentiels | B28: =COUNTIF('Autres données'!$A$5:$A$52,$A28) -> 3 | C28: =IFERROR(AVERAGEIFS('Autres données'!$G$5:$G$52,'Autres données'!$A$5:$A$52,$A28),"–") -> 2 | D28: =COUNTIFS('Autres données'!$A$5:$A$52,$A28,'Autres données'!$G$5:$G$52,0) -> 0
A29: Hydrologie | B29: =COUNTIF('Autres données'!$A$5:$A$52,$A29) -> 7 | C29: =IFERROR(AVERAGEIFS('Autres données'!$G$5:$G$52,'Autres données'!$A$5:$A$52,$A29),"–") -> 1.4285714 | D29: =COUNTIFS('Autres données'!$A$5:$A$52,$A29,'Autres données'!$G$5:$G$52,0) -> 0
A30: Normatif | B30: =COUNTIF('Autres données'!$A$5:$A$52,$A30) -> 1 | C30: =IFERROR(AVERAGEIFS('Autres données'!$G$5:$G$52,'Autres données'!$A$5:$A$52,$A30),"–") -> 2 | D30: =COUNTIFS('Autres données'!$A$5:$A$52,$A30,'Autres données'!$G$5:$G$52,0) -> 0
A31: Indicateurs | B31: =COUNTIF('Autres données'!$A$5:$A$52,$A31) -> 2 | C31: =IFERROR(AVERAGEIFS('Autres données'!$G$5:$G$52,'Autres données'!$A$5:$A$52,$A31),"–") -> 1.5 | D31: =COUNTIFS('Autres données'!$A$5:$A$52,$A31,'Autres données'!$G$5:$G$52,0) -> 0
A32: Filières | B32: =COUNTIF('Autres données'!$A$5:$A$52,$A32) -> 1 | C32: =IFERROR(AVERAGEIFS('Autres données'!$G$5:$G$52,'Autres données'!$A$5:$A$52,$A32),"–") -> 1 | D32: =COUNTIFS('Autres données'!$A$5:$A$52,$A32,'Autres données'!$G$5:$G$52,0) -> 0
A35: Ce qu'une meilleure donnée ne réglera pas
A36: Cultures tropicales | B36: Hors la jachère (« gel »), aucune culture de MOSAICA n'existe dans la base d'espèces de MAELIA. Chacune est à créer, avec le référent thématique : une colonne complète dans le fichier des espèces (la formation le fait avec « mon_espece »).
A37: Plantations pluriannuelles | B37: Canne (3 à 7 ans), banane (8 à 15 ans), agrumes et vergers (15 ans), ananas (18 mois) : la séquence MAELIA est annuelle et un ITK décrit une année, semis et récolte compris. Aucun mécanisme documenté ; vergers et vignes ne figurent pas dans le référentiel d'espèces de la grille d'enquête.
A38: Plafonds d'un ITK | B38: La grille d'enquête ITK prévoit un semis et une récolte par ITK, 4 apports, 8 traitements, 5 désherbages, 4 préparations du sol (les apports s'entendent par stratégie de fertilisation). 21 cultures sur 75 en sortent, soit 3614 ha observés en 2017, jusqu'à 34 passages de récolte par an pour BA_INT : colonne Dépassements de la feuille Cultures.
A39: Récolte | B39: La récolte attend la maturité en degrés-jours, puis elle est forcée en fin de fenêtre. Une campagne fixée par l'usine (canne) ou une récolte continue (banane, maraîchage) ne se décrivent pas ainsi.
A40: Prairies | B40: HerbSim ne connaît que 7 espèces tempérées et 5 types de graminées : les prairies naturelles tropicales, un quart de la surface observée, n'ont pas de paramètres. L'azote n'est plus un obstacle : le jeu de la formation fait tourner des prairies fauchées et pâturées avec AqYieldNC (HerbSimNC).
A41: Rendement potentiel | B41: RENDEMENT_OPTIMAL reste une entrée : le remplir avec Rdt_Cult reporterait la surestimation des rendements (vigilance C.1) dans MAELIA.
A42: Opérations sans type MAELIA | B42: Effeuillage, tuteurage, ensachage, emballage, soins aux animaux : jusqu'à 85 % des heures de la banane disparaissent à la traduction.
A43: Choix de l'ITK | B43: MOSAICA choisit la variante d'ITK, MAELIA la déduit de la situation. Deux pistes pour imposer une variante par parcelle sans créer une espèce par variante : la séquence de référence (ID_SDC de la parcelle, IDS_SDCS de l'ITK) et le critère libre CRIT_SPAT_ADHOC. À vérifier avec l'équipe.
A44: Calendrier tempéré | B44: La première année démarre en août ; un frein hivernal, un drapeau « culture d'hiver » et une fauche de fin d'été au 1er août sont dans le modèle. À passer en revue pour un climat sans hiver.
A45: Mécanisation | B45: D'après la note de 2022, les entrées OUTIL, PASSAGES et AGRIW n'ont pas d'effet sur la simulation : aucun conflit de matériel n'est simulé. À revérifier en 1.4.31.
...

Sheet Cultures
A1: Qualité des données par culture et par paramètre MAELIA
A2: 0 = absente, difficile · 1 = absente, accessible · 2 = disponible, à retravailler · 3 = utilisable · – = sans objet. Les notes sont modifiables : les moyennes et la feuille Synthèse suivent.
A3: Famille | B3: Code | C3: Culture | D3: Surface 2017 (ha) | E3: Modèle MAELIA | F3: Cycle | G3: Heures hors types MAELIA | H3: Dépassements des plafonds d'un ITK (passages par an) | I3: Espèce — AqYield : rendement, phénologie, eau (especesCultivees.csv) | Z3: Espèce — AqYieldNC : azote et carbone (especesCultivees.csv) | AN3: ITK (reglesDeDecisions.csv) | AZ3: Fertilisation | BB3: Économie | BG3: Moyennes de la ligne
I4: RENDEMENT_OPTIMAL | J4: RENDEMENT_MOYEN | K4: RENDEMENT_MIN | L4: Tbase | M4: Tmax | N4: DEGRES_J_LevTbase | O4: DEGRES_J_Flor | P4: DEGRES_J_matPhyTbase | Q4: FREIN | R4: KMAX | S4: CVIG | T4: CSTO | U4: coeff_Fonction_Prod | V4: CRACINE | W4: PROF_MAX_RACINE | X4: ZonesClimatiques | Y4: especesHerbSim.csv | Z4: BESOIN_N | AA4: Type_Nacq + courbe | AB4: adil, bdil, adilmax | AC4: N_grain | AD4: Tms | AE4: HI | AF4: SR_ratio | AG4: beta | AH4: C_aer, C_rac | AI4: CN_ratio | AJ4: Pse | AK4: ABSCISSION | AL4: isLEG | AM4: especeRepousse | AN4: ID_PREC | AO4: ZONE_PEDO, TYPE_EXPL, CLIMAT, IDS_SDCS | AP4: MATERIEL | AQ4: IS_<OT> | AR4: <OT>_TEMPS | AS4: <OT>_DEBUT / _FIN | AT4: Seuils de déclenchement | AU4: TRAVAIL_SOL_EFFET_RUs | AV4: IRRIGATION_DOSE, _TD | AW4: IRRIGATION fenêtre, stades, seuils | AX4: PHYTO produits, doses | AY4: FAUCHE, PATURE | AZ4: FERTIALT produit, dose N-P-K | BA4: FERTIALT calendrier, alternatives | BB4: prixVentes.csv | BC4: primes.csv | BD4: Prix des intrants | BE4: chargesOp.csv | BF4: chargesDePassage.csv | BG4: Espèce : eau, phéno | BH4: Espèce : N et C | BI4: ITK | BJ4: Fertilisation | BK4: Économie | BL4: Score global | BM4: Paramètres à 0
A5: Canne à sucre et canne fibre | B5: CS_NGT_NIM | C5: Canne à sucre : Nord Grande-Terre, pluvial, récolte mécanisée | D5: 3365.9 | E5: AqYield / AqYieldNC | F5: plantation de 7 ans | G5: 0.12 | I5: 1 | J5: 2 | K5: 2 | L5: 1 | M5: 1 | N5: 1 | O5: 1 | P5: 1 | Q5: 3 | R5: 1 | S5: 0 | T5: 1 | U5: 1 | V5: 0 | W5: 2 | X5: 2 | Y5: – | Z5: 1 | AA5: 0 | AB5: 1 | AC5: 1 | AD5: 1 | AE5: 2 | AF5: 2 | AG5: 1 | AH5: 2 | AI5: 1 | AJ5: 1 | AK5: 1 | AL5: 3 | AM5: 0 | AN5: 2 | AO5: 2 | AP5: – | AQ5: 2 | AR5: 2 | AS5: 1 | AT5: 0 | AU5: 2 | AV5: – | AW5: – | AX5: 3 | AY5: – | AZ5: 3 | BA5: 1 | BB5: 2 | BC5: 2 | BD5: 2 | BE5: 2 | BF5: 0 | BG5: =IFERROR(AVERAGE(I5:Y5),"–") -> 1.25 | BH5: =IFERROR(AVERAGE(Z5:AM5),"–") -> 1.2142857 | BI5: =IFERROR(AVERAGE(AN5:AY5),"–") -> 1.75 | BJ5: =IFERROR(AVERAGE(AZ5:BA5),"–") -> 2 | BK5: =IFERROR(AVERAGE(BB5:BF5),"–") -> 1.6 | BL5: =IFERROR(AVERAGE(I5:BF5),"–") -> 1.4 | BM5: =COUNTIF(I5:BF5,0) -> 6
A6: Canne à sucre et canne fibre | B6: CS_BT_NIM | C6: Canne à sucre : Basse-Terre, pluvial, récolte mécanisée | D6: 3349.2 | E6: AqYield / AqYieldNC | F6: plantation de 7 ans | G6: 0.12 | I6: 1 | J6: 2 | K6: 2 | L6: 1 | M6: 1 | N6: 1 | O6: 1 | P6: 1 | Q6: 3 | R6: 1 | S6: 0 | T6: 1 | U6: 1 | V6: 0 | W6: 2 | X6: 2 | Y6: – | Z6: 1 | AA6: 0 | AB6: 1 | AC6: 1 | AD6: 1 | AE6: 2 | AF6: 2 | AG6: 1 | AH6: 2 | AI6: 1 | AJ6: 1 | AK6: 1 | AL6: 3 | AM6: 0 | AN6: 2 | AO6: 2 | AP6: – | AQ6: 2 | AR6: 2 | AS6: 1 | AT6: 0 | AU6: 2 | AV6: – | AW6: – | AX6: 3 | AY6: – | AZ6: 3 | BA6: 1 | BB6: 2 | BC6: 2 | BD6: 2 | BE6: 2 | BF6: 0 | BG6: =IFERROR(AVERAGE(I6:Y6),"–") -> 1.25 | BH6: =IFERROR(AVERAGE(Z6:AM6),"–") -> 1.2142857 | BI6: =IFERROR(AVERAGE(AN6:AY6),"–") -> 1.75 | BJ6: =IFERROR(AVERAGE(AZ6:BA6),"–") -> 2 | BK6: =IFERROR(AVERAGE(BB6:BF6),"–") -> 1.6 | BL6: =IFERROR(AVERAGE(I6:BF6),"–") -> 1.4 | BM6: =COUNTIF(I6:BF6,0) -> 6
A7: Canne à sucre et canne fibre | B7: CS_MG_NISM | C7: Canne à sucre : Marie-Galante, pluvial, récolte semi-mécanisée | D7: 2186.1 | E7: AqYield / AqYieldNC | F7: plantation de 7 ans | G7: 0.12 | I7: 1 | J7: 2 | K7: 1 | L7: 1 | M7: 1 | N7: 1 | O7: 1 | P7: 1 | Q7: 3 | R7: 1 | S7: 0 | T7: 1 | U7: 1 | V7: 0 | W7: 2 | X7: 2 | Y7: – | Z7: 1 | AA7: 0 | AB7: 1 | AC7: 1 | AD7: 1 | AE7: 2 | AF7: 2 | AG7: 1 | AH7: 2 | AI7: 1 | AJ7: 1 | AK7: 1 | AL7: 3 | AM7: 0 | AN7: 2 | AO7: 2 | AP7: – | AQ7: 2 | AR7: 2 | AS7: 1 | AT7: 0 | AU7: 2 | AV7: – | AW7: – | AX7: 3 | AY7: – | AZ7: 3 | BA7: 1 | BB7: 2 | BC7: 2 | BD7: 2 | BE7: 2 | BF7: 0 | BG7: =IFERROR(AVERAGE(I7:Y7),"–") -> 1.1875 | BH7: =IFERROR(AVERAGE(Z7:AM7),"–") -> 1.2142857 | BI7: =IFERROR(AVERAGE(AN7:AY7),"–") -> 1.75 | BJ7: =IFERROR(AVERAGE(AZ7:BA7),"–") -> 2 | BK7: =IFERROR(AVERAGE(BB7:BF7),"–") -> 1.6 | BL7: =IFERROR(AVERAGE(I7:BF7),"–") -> 1.3777778 | BM7: =COUNTIF(I7:BF7,0) -> 6
A8: Canne à sucre et canne fibre | B8: CS_EGT_NIM | C8: Canne à sucre : Est Grande-Terre, pluvial, récolte mécanisée | D8: 1964.9 | E8: AqYield / AqYieldNC | F8: plantation de 7 ans | G8: 0.12 | I8: 1 | J8: 2 | K8: 2 | L8: 1 | M8: 1 | N8: 1 | O8: 1 | P8: 1 | Q8: 3 | R8: 1 | S8: 0 | T8: 1 | U8: 1 | V8: 0 | W8: 2 | X8: 2 | Y8: – | Z8: 1 | AA8: 0 | AB8: 1 | AC8: 1 | AD8: 1 | AE8: 2 | AF8: 2 | AG8: 1 | AH8: 2 | AI8: 1 | AJ8: 1 | AK8: 1 | AL8: 3 | AM8: 0 | AN8: 2 | AO8: 2 | AP8: – | AQ8: 2 | AR8: 2 | AS8: 1 | AT8: 0 | AU8: 2 | AV8: – | AW8: – | AX8: 3 | AY8: – | AZ8: 3 | BA8: 1 | BB8: 2 | BC8: 2 | BD8: 2 | BE8: 2 | BF8: 0 | BG8: =IFERROR(AVERAGE(I8:Y8),"–") -> 1.25 | BH8: =IFERROR(AVERAGE(Z8:AM8),"–") -> 1.2142857 | BI8: =IFERROR(AVERAGE(AN8:AY8),"–") -> 1.75 | BJ8: =IFERROR(AVERAGE(AZ8:BA8),"–") -> 2 | BK8: =IFERROR(AVERAGE(BB8:BF8),"–") -> 1.6 | BL8: =IFERROR(AVERAGE(I8:BF8),"–") -> 1.4 | BM8: =COUNTIF(I8:BF8,0) -> 6
A9: Canne à sucre et canne fibre | B9: CS_CGT_NIM | C9: Canne à sucre : Centre Grande-Terre, pluvial, récolte mécanisée | D9: 773.7 | E9: AqYield / AqYieldNC | F9: plantation de 7 ans | G9: 0.12 | I9: 1 | J9: 2 | K9: 2 | L9: 1 | M9: 1 | N9: 1 | O9: 1 | P9: 1 | Q9: 3 | R9: 1 | S9: 0 | T9: 1 | U9: 1 | V9: 0 | W9: 2 | X9: 2 | Y9: – | Z9: 1 | AA9: 0 | AB9: 1 | AC9: 1 | AD9: 1 | AE9: 2 | AF9: 2 | AG9: 1 | AH9: 2 | AI9: 1 | AJ9: 1 | AK9: 1 | AL9: 3 | AM9: 0 | AN9: 2 | AO9: 2 | AP9: – | AQ9: 2 | AR9: 2 | AS9: 1 | AT9: 0 | AU9: 2 | AV9: – | AW9: – | AX9: 3 | AY9: – | AZ9: 3 | BA9: 1 | BB9: 2 | BC9: 2 | BD9: 2 | BE9: 2 | BF9: 0 | BG9: =IFERROR(AVERAGE(I9:Y9),"–") -> 1.25 | BH9: =IFERROR(AVERAGE(Z9:AM9),"–") -> 1.2142857 | BI9: =IFERROR(AVERAGE(AN9:AY9),"–") -> 1.75 | BJ9: =IFERROR(AVERAGE(AZ9:BA9),"–") -> 2 | BK9: =IFERROR(AVERAGE(BB9:BF9),"–") -> 1.6 | BL9: =IFERROR(AVERAGE(I9:BF9),"–") -> 1.4 | BM9: =COUNTIF(I9:BF9,0) -> 6
A10: Canne à sucre et canne fibre | B10: CS_NGT_NISM | C10: Canne à sucre : Nord Grande-Terre, pluvial, récolte semi-mécanisée | D10: 653.8 | E10: AqYield / AqYieldNC | F10: plantation de 7 ans | G10: 0.12 | I10: 1 | J10: 2 | K10: 2 | L10: 1 | M10: 1 | N10: 1 | O10: 1 | P10: 1 | Q10: 3 | R10: 1 | S10: 0 | T10: 1 | U10: 1 | V10: 0 | W10: 2 | X10: 2 | Y10: – | Z10: 1 | AA10: 0 | AB10: 1 | AC10: 1 | AD10: 1 | AE10: 2 | AF10: 2 | AG10: 1 | AH10: 2 | AI10: 1 | AJ10: 1 | AK10: 1 | AL10: 3 | AM10: 0 | AN10: 2 | AO10: 2 | AP10: – | AQ10: 2 | AR10: 2 | AS10: 1 | AT10: 0 | AU10: 2 | AV10: – | AW10: – | AX10: 3 | AY10: – | AZ10: 3 | BA10: 1 | BB10: 2 | BC10: 2 | BD10: 2 | BE10: 2 | BF10: 0 | BG10: =IFERROR(AVERAGE(I10:Y10),"–") -> 1.25 | BH10: =IFERROR(AVERAGE(Z10:AM10),"–") -> 1.2142857 | BI10: =IFERROR(AVERAGE(AN10:AY10),"–") -> 1.75 | BJ10: =IFERROR(AVERAGE(AZ10:BA10),"–") -> 2 | BK10: =IFERROR(AVERAGE(BB10:BF10),"–") -> 1.6 | BL10: =IFERROR(AVERAGE(I10:BF10),"–") -> 1.4 | BM10: =COUNTIF(I10:BF10,0) -> 6
A11: Canne à sucre et canne fibre | B11: CS_SBT_NIM | C11: Canne à sucre : Sud-Est Basse-Terre, pluvial, récolte mécanisée | D11: 318.7 | E11: AqYield / AqYieldNC | F11: plantation de 3 ans | G11: 0.21 | I11: 1 | J11: 2 | K11: 2 | L11: 1 | M11: 1 | N11: 1 | O11: 1 | P11: 1 | Q11: 3 | R11: 1 | S11: 0 | T11: 1 | U11: 1 | V11: 0 | W11: 2 | X11: 2 | Y11: – | Z11: 1 | AA11: 0 | AB11: 1 | AC11: 1 | AD11: 1 | AE11: 2 | AF11: 2 | AG11: 1 | AH11: 2 | AI11: 1 | AJ11: 1 | AK11: 1 | AL11: 3 | AM11: 0 | AN11: 2 | AO11: 2 | AP11: – | AQ11: 2 | AR11: 2 | AS11: 1 | AT11: 0 | AU11: 2 | AV11: – | AW11: – | AX11: 3 | AY11: – | AZ11: 3 | BA11: 1 | BB11: 2 | BC11: 2 | BD11: 2 | BE11: 2 | BF11: 0 | BG11: =IFERROR(AVERAGE(I11:Y11),"–") -> 1.25 | BH11: =IFERROR(AVERAGE(Z11:AM11),"–") -> 1.2142857 | BI11: =IFERROR(AVERAGE(AN11:AY11),"–") -> 1.75 | BJ11: =IFERROR(AVERAGE(AZ11:BA11),"–") -> 2 | BK11: =IFERROR(AVERAGE(BB11:BF11),"–") -> 1.6 | BL11: =IFERROR(AVERAGE(I11:BF11),"–") -> 1.4 | BM11: =COUNTIF(I11:BF11,0) -> 6
A12: Canne à sucre et canne fibre | B12: CS_EGT_NISM | C12: Canne à sucre : Est Grande-Terre, pluvial, récolte semi-mécanisée | D12: 186.2 | E12: AqYield / AqYieldNC | F12: plantation de 7 ans | G12: 0.12 | I12: 1 | J12: 2 | K12: 2 | L12: 1 | M12: 1 | N12: 1 | O12: 1 | P12: 1 | Q12: 3 | R12: 1 | S12: 0 | T12: 1 | U12: 1 | V12: 0 | W12: 2 | X12: 2 | Y12: – | Z12: 1 | AA12: 0 | AB12: 1 | AC12: 1 | AD12: 1 | AE12: 2 | AF12: 2 | AG12: 1 | AH12: 2 | AI12: 1 | AJ12: 1 | AK12: 1 | AL12: 3 | AM12: 0 | AN12: 2 | AO12: 2 | AP12: – | AQ12: 2 | AR12: 2 | AS12: 1 | AT12: 0 | AU12: 2 | AV12: – | AW12: – | AX12: 3 | AY12: – | AZ12: 3 | BA12: 1 | BB12: 2 | BC12: 2 | BD12: 2 | BE12: 2 | BF12: 0 | BG12: =IFERROR(AVERAGE(I12:Y12),"–") -> 1.25 | BH12: =IFERROR(AVERAGE(Z12:AM12),"–") -> 1.2142857 | BI12: =IFERROR(AVERAGE(AN12:AY12),"–") -> 1.75 | BJ12: =IFERROR(AVERAGE(AZ12:BA12),"–") -> 2 | BK12: =IFERROR(AVERAGE(BB12:BF12),"–") -> 1.6 | BL12: =IFERROR(AVERAGE(I12:BF12),"–") -> 1.4 | BM12: =COUNTIF(I12:BF12,0) -> 6
A13: Canne à sucre et canne fibre | B13: CS_BT_NISM | C13: Canne à sucre : Basse-Terre, pluvial, récolte semi-mécanisée | D13: 12.3 | E13: AqYield / AqYieldNC | F13: plantation de 7 ans | G13: 0.12 | I13: 1 | J13: 2 | K13: 2 | L13: 1 | M13: 1 | N13: 1 | O13: 1 | P13: 1 | Q13: 3 | R13: 1 | S13: 0 | T13: 1 | U13: 1 | V13: 0 | W13: 2 | X13: 2 | Y13: – | Z13: 1 | AA13: 0 | AB13: 1 | AC13: 1 | AD13: 1 | AE13: 2 | AF13: 2 | AG13: 1 | AH13: 2 | AI13: 1 | AJ13: 1 | AK13: 1 | AL13: 3 | AM13: 0 | AN13: 2 | AO13: 2 | AP13: – | AQ13: 2 | AR13: 2 | AS13: 1 | AT13: 0 | AU13: 2 | AV13: – | AW13: – | AX13: 3 | AY13: – | AZ13: 3 | BA13: 1 | BB13: 2 | BC13: 2 | BD13: 2 | BE13: 2 | BF13: 0 | BG13: =IFERROR(AVERAGE(I13:Y13),"–") -> 1.25 | BH13: =IFERROR(AVERAGE(Z13:AM13),"–") -> 1.2142857 | BI13: =IFERROR(AVERAGE(AN13:AY13),"–") -> 1.75 | BJ13: =IFERROR(AVERAGE(AZ13:BA13),"–") -> 2 | BK13: =IFERROR(AVERAGE(BB13:BF13),"–") -> 1.6 | BL13: =IFERROR(AVERAGE(I13:BF13),"–") -> 1.4 | BM13: =COUNTIF(I13:BF13,0) -> 6
A14: Canne à sucre et canne fibre | B14: CS_CGT_NISM | C14: Canne à sucre : Centre Grande-Terre, pluvial, récolte semi-mécanisée | D14: 2.1 | E14: AqYield / AqYieldNC | F14: plantation de 7 ans | G14: 0.12 | I14: 1 | J14: 2 | K14: 2 | L14: 1 | M14: 1 | N14: 1 | O14: 1 | P14: 1 | Q14: 3 | R14: 1 | S14: 0 | T14: 1 | U14: 1 | V14: 0 | W14: 2 | X14: 2 | Y14: – | Z14: 1 | AA14: 0 | AB14: 1 | AC14: 1 | AD14: 1 | AE14: 2 | AF14: 2 | AG14: 1 | AH14: 2 | AI14: 1 | AJ14: 1 | AK14: 1 | AL14: 3 | AM14: 0 | AN14: 2 | AO14: 2 | AP14: – | AQ14: 2 | AR14: 2 | AS14: 1 | AT14: 0 | AU14: 2 | AV14: – | AW14: – | AX14: 3 | AY14: – | AZ14: 3 | BA14: 1 | BB14: 2 | BC14: 2 | BD14: 2 | BE14: 2 | BF14: 0 | BG14: =IFERROR(AVERAGE(I14:Y14),"–") -> 1.25 | BH14: =IFERROR(AVERAGE(Z14:AM14),"–") -> 1.2142857 | BI14: =IFERROR(AVERAGE(AN14:AY14),"–") -> 1.75 | BJ14: =IFERROR(AVERAGE(AZ14:BA14),"–") -> 2 | BK14: =IFERROR(AVERAGE(BB14:BF14),"–") -> 1.6 | BL14: =IFERROR(AVERAGE(I14:BF14),"–") -> 1.4 | BM14: =COUNTIF(I14:BF14,0) -> 6
A15: Canne à sucre et canne fibre | B15: CF_CGT_NIM | C15: Canne fibre : Centre Grande-Terre, pluvial, récolte mécanisée | D15: 0 | E15: AqYield / AqYieldNC | F15: plantation de 6 ans | G15: 0.14 | I15: 1 | J15: 2 | K15: 2 | L15: 1 | M15: 1 | N15: 1 | O15: 1 | P15: 1 | Q15: 3 | R15: 1 | S15: 0 | T15: 1 | U15: 1 | V15: 0 | W15: 2 | X15: 2 | Y15: – | Z15: 1 | AA15: 0 | AB15: 1 | AC15: 1 | AD15: 1 | AE15: 2 | AF15: 2 | AG15: 1 | AH15: 2 | AI15: 1 | AJ15: 1 | AK15: 1 | AL15: 3 | AM15: 0 | AN15: 2 | AO15: 2 | AP15: – | AQ15: 2 | AR15: 2 | AS15: 1 | AT15: 0 | AU15: 2 | AV15: – | AW15: – | AX15: 3 | AY15: – | AZ15: 3 | BA15: 1 | BB15: 1 | BC15: 2 | BD15: 2 | BE15: 2 | BF15: 0 | BG15: =IFERROR(AVERAGE(I15:Y15),"–") -> 1.25 | BH15: =IFERROR(AVERAGE(Z15:AM15),"–") -> 1.2142857 | BI15: =IFERROR(AVERAGE(AN15:AY15),"–") -> 1.75 | BJ15: =IFERROR(AVERAGE(AZ15:BA15),"–") -> 2 | BK15: =IFERROR(AVERAGE(BB15:BF15),"–") -> 1.4 | BL15: =IFERROR(AVERAGE(I15:BF15),"–") -> 1.3777778 | BM15: =COUNTIF(I15:BF15,0) -> 6
A16: Canne à sucre et canne fibre | B16: CF_CGT_NISM | C16: Canne fibre : Centre Grande-Terre, pluvial, récolte semi-mécanisée | D16: 0 | E16: AqYield / AqYieldNC | F16: plantation de 6 ans | G16: 0.14 | I16: 1 | J16: 2 | K16: 2 | L16: 1 | M16: 1 | N16: 1 | O16: 1 | P16: 1 | Q16: 3 | R16: 1 | S16: 0 | T16: 1 | U16: 1 | V16: 0 | W16: 2 | X16: 2 | Y16: – | Z16: 1 | AA16: 0 | AB16: 1 | AC16: 1 | AD16: 1 | AE16: 2 | AF16: 2 | AG16: 1 | AH16: 2 | AI16: 1 | AJ16: 1 | AK16: 1 | AL16: 3 | AM16: 0 | AN16: 2 | AO16: 2 | AP16: – | AQ16: 2 | AR16: 2 | AS16: 1 | AT16: 0 | AU16: 2 | AV16: – | AW16: – | AX16: 3 | AY16: – | AZ16: 3 | BA16: 1 | BB16: 1 | BC16: 2 | BD16: 2 | BE16: 2 | BF16: 0 | BG16: =IFERROR(AVERAGE(I16:Y16),"–") -> 1.25 | BH16: =IFERROR(AVERAGE(Z16:AM16),"–") -> 1.2142857 | BI16: =IFERROR(AVERAGE(AN16:AY16),"–") -> 1.75 | BJ16: =IFERROR(AVERAGE(AZ16:BA16),"–") -> 2 | BK16: =IFERROR(AVERAGE(BB16:BF16),"–") -> 1.4 | BL16: =IFERROR(AVERAGE(I16:BF16),"–") -> 1.3777778 | BM16: =COUNTIF(I16:BF16,0) -> 6
A17: Canne à sucre et canne fibre | B17: CF_EGT_NIM | C17: Canne fibre : Est Grande-Terre, pluvial, récolte mécanisée | D17: 0 | E17: AqYield / AqYieldNC | F17: plantation de 6 ans | G17: 0.14 | H17: 2 récoltes (max 1) | I17: 1 | J17: 2 | K17: 2 | L17: 1 | M17: 1 | N17: 1 | O17: 1 | P17: 1 | Q17: 3 | R17: 1 | S17: 0 | T17: 1 | U17: 1 | V17: 0 | W17: 2 | X17: 2 | Y17: – | Z17: 1 | AA17: 0 | AB17: 1 | AC17: 1 | AD17: 1 | AE17: 2 | AF17: 2 | AG17: 1 | AH17: 2 | AI17: 1 | AJ17: 1 | AK17: 1 | AL17: 3 | AM17: 0 | AN17: 2 | AO17: 2 | AP17: – | AQ17: 2 | AR17: 2 | AS17: 1 | AT17: 0 | AU17: 2 | AV17: – | AW17: – | AX17: 3 | AY17: – | AZ17: 3 | BA17: 1 | BB17: 1 | BC17: 2 | BD17: 2 | BE17: 2 | BF17: 0 | BG17: =IFERROR(AVERAGE(I17:Y17),"–") -> 1.25 | BH17: =IFERROR(AVERAGE(Z17:AM17),"–") -> 1.2142857 | BI17: =IFERROR(AVERAGE(AN17:AY17),"–") -> 1.75 | BJ17: =IFERROR(AVERAGE(AZ17:BA17),"–") -> 2 | BK17: =IFERROR(AVERAGE(BB17:BF17),"–") -> 1.4 | BL17: =IFERROR(AVERAGE(I17:BF17),"–") -> 1.3777778 | BM17: =COUNTIF(I17:BF17,0) -> 6
A18: Canne à sucre et canne fibre | B18: CF_EGT_NISM | C18: Canne fibre : Est Grande-Terre, pluvial, récolte semi-mécanisée | D18: 0 | E18: AqYield / AqYieldNC | F18: plantation de 6 ans | G18: 0.14 | H18: 2 récoltes (max 1) | I18: 1 | J18: 2 | K18: 2 | L18: 1 | M18: 1 | N18: 1 | O18: 1 | P18: 1 | Q18: 3 | R18: 1 | S18: 0 | T18: 1 | U18: 1 | V18: 0 | W18: 2 | X18: 2 | Y18: – | Z18: 1 | AA18: 0 | AB18: 1 | AC18: 1 | AD18: 1 | AE18: 2 | AF18: 2 | AG18: 1 | AH18: 2 | AI18: 1 | AJ18: 1 | AK18: 1 | AL18: 3 | AM18: 0 | AN18: 2 | AO18: 2 | AP18: – | AQ18: 2 | AR18: 2 | AS18: 1 | AT18: 0 | AU18: 2 | AV18: – | AW18: – | AX18: 3 | AY18: – | AZ18: 3 | BA18: 1 | BB18: 1 | BC18: 2 | BD18: 2 | BE18: 2 | BF18: 0 | BG18: =IFERROR(AVERAGE(I18:Y18),"–") -> 1.25 | BH18: =IFERROR(AVERAGE(Z18:AM18),"–") -> 1.2142857 | BI18: =IFERROR(AVERAGE(AN18:AY18),"–") -> 1.75 | BJ18: =IFERROR(AVERAGE(AZ18:BA18),"–") -> 2 | BK18: =IFERROR(AVERAGE(BB18:BF18),"–") -> 1.4 | BL18: =IFERROR(AVERAGE(I18:BF18),"–") -> 1.3777778 | BM18: =COUNTIF(I18:BF18,0) -> 6
A19: Canne à sucre et canne fibre | B19: CF_NBT_NIM | C19: Canne fibre : Nord Basse-Terre, pluvial, récolte mécanisée | D19: 0 | E19: AqYield / AqYieldNC | F19: plantation de 6 ans | G19: 0.14 | I19: 1 | J19: 2 | K19: 2 | L19: 1 | M19: 1 | N19: 1 | O19: 1 | P19: 1 | Q19: 3 | R19: 1 | S19: 0 | T19: 1 | U19: 1 | V19: 0 | W19: 2 | X19: 2 | Y19: – | Z19: 1 | AA19: 0 | AB19: 1 | AC19: 1 | AD19: 1 | AE19: 2 | AF19: 2 | AG19: 1 | AH19: 2 | AI19: 1 | AJ19: 1 | AK19: 1 | AL19: 3 | AM19: 0 | AN19: 2 | AO19: 2 | AP19: – | AQ19: 2 | AR19: 2 | AS19: 1 | AT19: 0 | AU19: 2 | AV19: – | AW19: – | AX19: 3 | AY19: – | AZ19: 3 | BA19: 1 | BB19: 1 | BC19: 2 | BD19: 2 | BE19: 2 | BF19: 0 | BG19: =IFERROR(AVERAGE(I19:Y19),"–") -> 1.25 | BH19: =IFERROR(AVERAGE(Z19:AM19),"–") -> 1.2142857 | BI19: =IFERROR(AVERAGE(AN19:AY19),"–") -> 1.75 | BJ19: =IFERROR(AVERAGE(AZ19:BA19),"–") -> 2 | BK19: =IFERROR(AVERAGE(BB19:BF19),"–") -> 1.4 | BL19: =IFERROR(AVERAGE(I19:BF19),"–") -> 1.3777778 | BM19: =COUNTIF(I19:BF19,0) -> 6
A20: Canne à sucre et canne fibre | B20: CF_NBT_NISM | C20: Canne fibre : Nord Basse-Terre, pluvial, récolte semi-mécanisée | D20: 0 | E20: AqYield / AqYieldNC | F20: plantation de 6 ans | G20: 0.14 | I20: 1 | J20: 2 | K20: 2 | L20: 1 | M20: 1 | N20: 1 | O20: 1 | P20: 1 | Q20: 3 | R20: 1 | S20: 0 | T20: 1 | U20: 1 | V20: 0 | W20: 2 | X20: 2 | Y20: – | Z20: 1 | AA20: 0 | AB20: 1 | AC20: 1 | AD20: 1 | AE20: 2 | AF20: 2 | AG20: 1 | AH20: 2 | AI20: 1 | AJ20: 1 | AK20: 1 | AL20: 3 | AM20: 0 | AN20: 2 | AO20: 2 | AP20: – | AQ20: 2 | AR20: 2 | AS20: 1 | AT20: 0 | AU20: 2 | AV20: – | AW20: – | AX20: 3 | AY20: – | AZ20: 3 | BA20: 1 | BB20: 1 | BC20: 2 | BD20: 2 | BE20: 2 | BF20: 0 | BG20: =IFERROR(AVERAGE(I20:Y20),"–") -> 1.25 | BH20: =IFERROR(AVERAGE(Z20:AM20),"–") -> 1.2142857 | BI20: =IFERROR(AVERAGE(AN20:AY20),"–") -> 1.75 | BJ20: =IFERROR(AVERAGE(AZ20:BA20),"–") -> 2 | BK20: =IFERROR(AVERAGE(BB20:BF20),"–") -> 1.4 | BL20: =IFERROR(AVERAGE(I20:BF20),"–") -> 1.3777778 | BM20: =COUNTIF(I20:BF20,0) -> 6
A21: Canne à sucre et canne fibre | B21: CF_NGT_NIM | C21: Canne fibre : Nord Grande-Terre, pluvial, récolte mécanisée | D21: 0 | E21: AqYield / AqYieldNC | F21: plantation de 6 ans | G21: 0.14 | H21: 2 récoltes (max 1) | I21: 1 | J21: 2 | K21: 2 | L21: 1 | M21: 1 | N21: 1 | O21: 1 | P21: 1 | Q21: 3 | R21: 1 | S21: 0 | T21: 1 | U21: 1 | V21: 0 | W21: 2 | X21: 2 | Y21: – | Z21: 1 | AA21: 0 | AB21: 1 | AC21: 1 | AD21: 1 | AE21: 2 | AF21: 2 | AG21: 1 | AH21: 2 | AI21: 1 | AJ21: 1 | AK21: 1 | AL21: 3 | AM21: 0 | AN21: 2 | AO21: 2 | AP21: – | AQ21: 2 | AR21: 2 | AS21: 1 | AT21: 0 | AU21: 2 | AV21: – | AW21: – | AX21: 3 | AY21: – | AZ21: 3 | BA21: 1 | BB21: 1 | BC21: 2 | BD21: 2 | BE21: 2 | BF21: 0 | BG21: =IFERROR(AVERAGE(I21:Y21),"–") -> 1.25 | BH21: =IFERROR(AVERAGE(Z21:AM21),"–") -> 1.2142857 | BI21: =IFERROR(AVERAGE(AN21:AY21),"–") -> 1.75 | BJ21: =IFERROR(AVERAGE(AZ21:BA21),"–") -> 2 | BK21: =IFERROR(AVERAGE(BB21:BF21),"–") -> 1.4 | BL21: =IFERROR(AVERAGE(I21:BF21),"–") -> 1.3777778 | BM21: =COUNTIF(I21:BF21,0) -> 6
A22: Canne à sucre et canne fibre | B22: CF_NGT_NISM | C22: Canne fibre : Nord Grande-Terre, pluvial, récolte semi-mécanisée | D22: 0 | E22: AqYield / AqYieldNC | F22: plantation de 6 ans | G22: 0.14 | H22: 2 récoltes (max 1) | I22: 1 | J22: 2 | K22: 2 | L22: 1 | M22: 1 | N22: 1 | O22: 1 | P22: 1 | Q22: 3 | R22: 1 | S22: 0 | T22: 1 | U22: 1 | V22: 0 | W22: 2 | X22: 2 | Y22: – | Z22: 1 | AA22: 0 | AB22: 1 | AC22: 1 | AD22: 1 | AE22: 2 | AF22: 2 | AG22: 1 | AH22: 2 | AI22: 1 | AJ22: 1 | AK22: 1 | AL22: 3 | AM22: 0 | AN22: 2 | AO22: 2 | AP22: – | AQ22: 2 | AR22: 2 | AS22: 1 | AT22: 0 | AU22: 2 | AV22: – | AW22: – | AX22: 3 | AY22: – | AZ22: 3 | BA22: 1 | BB22: 1 | BC22: 2 | BD22: 2 | BE22: 2 | BF22: 0 | BG22: =IFERROR(AVERAGE(I22:Y22),"–") -> 1.25 | BH22: =IFERROR(AVERAGE(Z22:AM22),"–") -> 1.2142857 | BI22: =IFERROR(AVERAGE(AN22:AY22),"–") -> 1.75 | BJ22: =IFERROR(AVERAGE(AZ22:BA22),"–") -> 2 | BK22: =IFERROR(AVERAGE(BB22:BF22),"–") -> 1.4 | BL22: =IFERROR(AVERAGE(I22:BF22),"–") -> 1.3777778 | BM22: =COUNTIF(I22:BF22,0) -> 6
A23: Canne à sucre et canne fibre | B23: CF_SBT_NIM | C23: Canne fibre : Sud Basse-Terre, pluvial, récolte mécanisée | D23: 0 | E23: AqYield / AqYieldNC | F23: plantation de 6 ans | G23: 0.14 | I23: 1 | J23: 2 | K23: 2 | L23: 1 | M23: 1 | N23: 1 | O23: 1 | P23: 1 | Q23: 3 | R23: 1 | S23: 0 | T23: 1 | U23: 1 | V23: 0 | W23: 2 | X23: 2 | Y23: – | Z23: 1 | AA23: 0 | AB23: 1 | AC23: 1 | AD23: 1 | AE23: 2 | AF23: 2 | AG23: 1 | AH23: 2 | AI23: 1 | AJ23: 1 | AK23: 1 | AL23: 3 | AM23: 0 | AN23: 2 | AO23: 2 | AP23: – | AQ23: 2 | AR23: 2 | AS23: 1 | AT23: 0 | AU23: 2 | AV23: – | AW23: – | AX23: 3 | AY23: – | AZ23: 3 | BA23: 1 | BB23: 1 | BC23: 2 | BD23: 2 | BE23: 2 | BF23: 0 | BG23: =IFERROR(AVERAGE(I23:Y23),"–") -> 1.25 | BH23: =IFERROR(AVERAGE(Z23:AM23),"–") -> 1.2142857 | BI23: =IFERROR(AVERAGE(AN23:AY23),"–") -> 1.75 | BJ23: =IFERROR(AVERAGE(AZ23:BA23),"–") -> 2 | BK23: =IFERROR(AVERAGE(BB23:BF23),"–") -> 1.4 | BL23: =IFERROR(AVERAGE(I23:BF23),"–") -> 1.3777778 | BM23: =COUNTIF(I23:BF23,0) -> 6
A24: Canne à sucre et canne fibre | B24: CF_SBT_NISM | C24: Canne fibre : Sud Basse-Terre, pluvial, récolte semi-mécanisée | D24: 0 | E24: AqYield / AqYieldNC | F24: plantation de 6 ans | G24: 0.14 | I24: 1 | J24: 2 | K24: 2 | L24: 1 | M24: 1 | N24: 1 | O24: 1 | P24: 1 | Q24: 3 | R24: 1 | S24: 0 | T24: 1 | U24: 1 | V24: 0 | W24: 2 | X24: 2 | Y24: – | Z24: 1 | AA24: 0 | AB24: 1 | AC24: 1 | AD24: 1 | AE24: 2 | AF24: 2 | AG24: 1 | AH24: 2 | AI24: 1 | AJ24: 1 | AK24: 1 | AL24: 3 | AM24: 0 | AN24: 2 | AO24: 2 | AP24: – | AQ24: 2 | AR24: 2 | AS24: 1 | AT24: 0 | AU24: 2 | AV24: – | AW24: – | AX24: 3 | AY24: – | AZ24: 3 | BA24: 1 | BB24: 1 | BC24: 2 | BD24: 2 | BE24: 2 | BF24: 0 | BG24: =IFERROR(AVERAGE(I24:Y24),"–") -> 1.25 | BH24: =IFERROR(AVERAGE(Z24:AM24),"–") -> 1.2142857 | BI24: =IFERROR(AVERAGE(AN24:AY24),"–") -> 1.75 | BJ24: =IFERROR(AVERAGE(AZ24:BA24),"–") -> 2 | BK24: =IFERROR(AVERAGE(BB24:BF24),"–") -> 1.4 | BL24: =IFERROR(AVERAGE(I24:BF24),"–") -> 1.3777778 | BM24: =COUNTIF(I24:BF24,0) -> 6
A25: Canne à sucre et canne fibre | B25: CS_BT_IM | C25: Canne à sucre : Basse-Terre, irrigué, récolte mécanisée | D25: 0 | E25: AqYield / AqYieldNC | F25: plantation de 7 ans | G25: 0.22 | I25: 1 | J25: 2 | K25: 2 | L25: 1 | M25: 1 | N25: 1 | O25: 1 | P25: 1 | Q25: 3 | R25: 1 | S25: 0 | T25: 1 | U25: 1 | V25: 0 | W25: 2 | X25: 2 | Y25: – | Z25: 1 | AA25: 0 | AB25: 1 | AC25: 1 | AD25: 1 | AE25: 2 | AF25: 2 | AG25: 1 | AH25: 2 | AI25: 1 | AJ25: 1 | AK25: 1 | AL25: 3 | AM25: 0 | AN25: 2 | AO25: 2 | AP25: 1 | AQ25: 2 | AR25: 2 | AS25: 1 | AT25: 0 | AU25: 2 | AV25: 1 | AW25: 0 | AX25: 3 | AY25: – | AZ25: 3 | BA25: 1 | BB25: 2 | BC25: 2 | BD25: 2 | BE25: 2 | BF25: 0 | BG25: =IFERROR(AVERAGE(I25:Y25),"–") -> 1.25 | BH25: =IFERROR(AVERAGE(Z25:AM25),"–") -> 1.2142857 | BI25: =IFERROR(AVERAGE(AN25:AY25),"–") -> 1.4545455 | BJ25: =IFERROR(AVERAGE(AZ25:BA25),"–") -> 2 | BK25: =IFERROR(AVERAGE(BB25:BF25),"–") -> 1.6 | BL25: =IFERROR(AVERAGE(I25:BF25),"–") -> 1.3541667 | BM25: =COUNTIF(I25:BF25,0) -> 7
A26: Canne à sucre et canne fibre | B26: CS_CGT_IM | C26: Canne à sucre : Centre Grande-Terre, irrigué, récolte mécanisée | D26: 0 | E26: AqYield / AqYieldNC | F26: plantation de 7 ans | G26: 0.1 | I26: 1 | J26: 2 | K26: 2 | L26: 1 | M26: 1 | N26: 1 | O26: 1 | P26: 1 | Q26: 3 | R26: 1 | S26: 0 | T26: 1 | U26: 1 | V26: 0 | W26: 2 | X26: 2 | Y26: – | Z26: 1 | AA26: 0 | AB26: 1 | AC26: 1 | AD26: 1 | AE26: 2 | AF26: 2 | AG26: 1 | AH26: 2 | AI26: 1 | AJ26: 1 | AK26: 1 | AL26: 3 | AM26: 0 | AN26: 2 | AO26: 2 | AP26: 1 | AQ26: 2 | AR26: 3 | AS26: 1 | AT26: 0 | AU26: 2 | AV26: 1 | AW26: 0 | AX26: 3 | AY26: – | AZ26: 3 | BA26: 1 | BB26: 2 | BC26: 2 | BD26: 2 | BE26: 2 | BF26: 0 | BG26: =IFERROR(AVERAGE(I26:Y26),"–") -> 1.25 | BH26: =IFERROR(AVERAGE(Z26:AM26),"–") -> 1.2142857 | BI26: =IFERROR(AVERAGE(AN26:AY26),"–") -> 1.5454545 | BJ26: =IFERROR(AVERAGE(AZ26:BA26),"–") -> 2 | BK26: =IFERROR(AVERAGE(BB26:BF26),"–") -> 1.6 | BL26: =IFERROR(AVERAGE(I26:BF26),"–") -> 1.375 | BM26: =COUNTIF(I26:BF26,0) -> 7
A27: Canne à sucre et canne fibre | B27: CS_EGT_IM | C27: Canne à sucre : Est Grande-Terre, irrigué, récolte mécanisée | D27: 0 | E27: AqYield / AqYieldNC | F27: plantation de 7 ans | G27: 0.1 | I27: 1 | J27: 2 | K27: 2 | L27: 1 | M27: 1 | N27: 1 | O27: 1 | P27: 1 | Q27: 3 | R27: 1 | S27: 0 | T27: 1 | U27: 1 | V27: 0 | W27: 2 | X27: 2 | Y27: – | Z27: 1 | AA27: 0 | AB27: 1 | AC27: 1 | AD27: 1 | AE27: 2 | AF27: 2 | AG27: 1 | AH27: 2 | AI27: 1 | AJ27: 1 | AK27: 1 | AL27: 3 | AM27: 0 | AN27: 2 | AO27: 2 | AP27: 1 | AQ27: 2 | AR27: 3 | AS27: 1 | AT27: 0 | AU27: 2 | AV27: 1 | AW27: 0 | AX27: 3 | AY27: – | AZ27: 3 | BA27: 1 | BB27: 2 | BC27: 2 | BD27: 2 | BE27: 2 | BF27: 0 | BG27: =IFERROR(AVERAGE(I27:Y27),"–") -> 1.25 | BH27: =IFERROR(AVERAGE(Z27:AM27),"–") -> 1.2142857 | BI27: =IFERROR(AVERAGE(AN27:AY27),"–") -> 1.5454545 | BJ27: =IFERROR(AVERAGE(AZ27:BA27),"–") -> 2 | BK27: =IFERROR(AVERAGE(BB27:BF27),"–") -> 1.6 | BL27: =IFERROR(AVERAGE(I27:BF27),"–") -> 1.375 | BM27: =COUNTIF(I27:BF27,0) -> 7
A28: Canne à sucre et canne fibre | B28: CS_MG_IM | C28: Canne à sucre : Marie-Galante, irrigué, récolte mécanisée | D28: 0 | E28: AqYield / AqYieldNC | F28: plantation de 7 ans | G28: 0.1 | I28: 1 | J28: 2 | K28: 1 | L28: 1 | M28: 1 | N28: 1 | O28: 1 | P28: 1 | Q28: 3 | R28: 1 | S28: 0 | T28: 1 | U28: 1 | V28: 0 | W28: 2 | X28: 2 | Y28: – | Z28: 1 | AA28: 0 | AB28: 1 | AC28: 1 | AD28: 1 | AE28: 2 | AF28: 2 | AG28: 1 | AH28: 2 | AI28: 1 | AJ28: 1 | AK28: 1 | AL28: 3 | AM28: 0 | AN28: 2 | AO28: 2 | AP28: 1 | AQ28: 2 | AR28: 3 | AS28: 1 | AT28: 0 | AU28: 2 | AV28: 1 | AW28: 0 | AX28: 3 | AY28: – | AZ28: 3 | BA28: 1 | BB28: 2 | BC28: 2 | BD28: 2 | BE28: 2 | BF28: 0 | BG28: =IFERROR(AVERAGE(I28:Y28),"–") -> 1.1875 | BH28: =IFERROR(AVERAGE(Z28:AM28),"–") -> 1.2142857 | BI28: =IFERROR(AVERAGE(AN28:AY28),"–") -> 1.5454545 | BJ28: =IFERROR(AVERAGE(AZ28:BA28),"–") -> 2 | BK28: =IFERROR(AVERAGE(BB28:BF28),"–") -> 1.6 | BL28: =IFERROR(AVERAGE(I28:BF28),"–") -> 1.3541667 | BM28: =COUNTIF(I28:BF28,0) -> 7
A29: Canne à sucre et canne fibre | B29: CS_MG_NIM | C29: Canne à sucre : Marie-Galante, pluvial, récolte mécanisée | D29: 0 | E29: AqYield / AqYieldNC | F29: plantation de 7 ans | G29: 0.12 | I29: 1 | J29: 2 | K29: 1 | L29: 1 | M29: 1 | N29: 1 | O29: 1 | P29: 1 | Q29: 3 | R29: 1 | S29: 0 | T29: 1 | U29: 1 | V29: 0 | W29: 2 | X29: 2 | Y29: – | Z29: 1 | AA29: 0 | AB29: 1 | AC29: 1 | AD29: 1 | AE29: 2 | AF29: 2 | AG29: 1 | AH29: 2 | AI29: 1 | AJ29: 1 | AK29: 1 | AL29: 3 | AM29: 0 | AN29: 2 | AO29: 2 | AP29: – | AQ29: 2 | AR29: 2 | AS29: 1 | AT29: 0 | AU29: 2 | AV29: – | AW29: – | AX29: 3 | AY29: – | AZ29: 3 | BA29: 1 | BB29: 2 | BC29: 2 | BD29: 2 | BE29: 2 | BF29: 0 | BG29: =IFERROR(AVERAGE(I29:Y29),"–") -> 1.1875 | BH29: =IFERROR(AVERAGE(Z29:AM29),"–") -> 1.2142857 | BI29: =IFERROR(AVERAGE(AN29:AY29),"–") -> 1.75 | BJ29: =IFERROR(AVERAGE(AZ29:BA29),"–") -> 2 | BK29: =IFERROR(AVERAGE(BB29:BF29),"–") -> 1.6 | BL29: =IFERROR(AVERAGE(I29:BF29),"–") -> 1.3777778 | BM29: =COUNTIF(I29:BF29,0) -> 6
A30: Canne à sucre et canne fibre | B30: CS_NGT_IM | C30: Canne à sucre : Nord Grande-Terre, irrigué, récolte mécanisée | D30: 0 | E30: AqYield / AqYieldNC | F30: plantation de 7 ans | G30: 0.1 | I30: 1 | J30: 2 | K30: 2 | L30: 1 | M30: 1 | N30: 1 | O30: 1 | P30: 1 | Q30: 3 | R30: 1 | S30: 0 | T30: 1 | U30: 1 | V30: 0 | W30: 2 | X30: 2 | Y30: – | Z30: 1 | AA30: 0 | AB30: 1 | AC30: 1 | AD30: 1 | AE30: 2 | AF30: 2 | AG30: 1 | AH30: 2 | AI30: 1 | AJ30: 1 | AK30: 1 | AL30: 3 | AM30: 0 | AN30: 2 | AO30: 2 | AP30: 1 | AQ30: 2 | AR30: 3 | AS30: 1 | AT30: 0 | AU30: 2 | AV30: 1 | AW30: 0 | AX30: 3 | AY30: – | AZ30: 3 | BA30: 1 | BB30: 2 | BC30: 2 | BD30: 2 | BE30: 2 | BF30: 0 | BG30: =IFERROR(AVERAGE(I30:Y30),"–") -> 1.25 | BH30: =IFERROR(AVERAGE(Z30:AM30),"–") -> 1.2142857 | BI30: =IFERROR(AVERAGE(AN30:AY30),"–") -> 1.5454545 | BJ30: =IFERROR(AVERAGE(AZ30:BA30),"–") -> 2 | BK30: =IFERROR(AVERAGE(BB30:BF30),"–") -> 1.6 | BL30: =IFERROR(AVERAGE(I30:BF30),"–") -> 1.375 | BM30: =COUNTIF(I30:BF30,0) -> 7
A31: Canne à sucre et canne fibre | B31: CS_SBT_IM | C31: Canne à sucre : Sud-Est Basse-Terre, irrigué, récolte mécanisée | D31: 0 | E31: AqYield / AqYieldNC | F31: plantation de 3 ans | G31: 0.14 | I31: 1 | J31: 2 | K31: 2 | L31: 1 | M31: 1 | N31: 1 | O31: 1 | P31: 1 | Q31: 3 | R31: 1 | S31: 0 | T31: 1 | U31: 1 | V31: 0 | W31: 2 | X31: 2 | Y31: – | Z31: 1 | AA31: 0 | AB31: 1 | AC31: 1 | AD31: 1 | AE31: 2 | AF31: 2 | AG31: 1 | AH31: 2 | AI31: 1 | AJ31: 1 | AK31: 1 | AL31: 3 | AM31: 0 | AN31: 2 | AO31: 2 | AP31: 1 | AQ31: 2 | AR31: 2 | AS31: 1 | AT31: 0 | AU31: 2 | AV31: 1 | AW31: 0 | AX31: 3 | AY31: – | AZ31: 3 | BA31: 1 | BB31: 2 | BC31: 2 | BD31: 2 | BE31: 2 | BF31: 0 | BG31: =IFERROR(AVERAGE(I31:Y31),"–") -> 1.25 | BH31: =IFERROR(AVERAGE(Z31:AM31),"–") -> 1.2142857 | BI31: =IFERROR(AVERAGE(AN31:AY31),"–") -> 1.4545455 | BJ31: =IFERROR(AVERAGE(AZ31:BA31),"–") -> 2 | BK31: =IFERROR(AVERAGE(BB31:BF31),"–") -> 1.6 | BL31: =IFERROR(AVERAGE(I31:BF31),"–") -> 1.3541667 | BM31: =COUNTIF(I31:BF31,0) -> 7
A32: Canne à sucre et canne fibre | B32: CS_SBT_NISM | C32: Canne à sucre : Sud-Est Basse-Terre, pluvial, récolte semi-mécanisée | D32: 0 | E32: AqYield / AqYieldNC | F32: plantation de 3 ans | G32: 0.21 | I32: 1 | J32: 2 | K32: 2 | L32: 1 | M32: 1 | N32: 1 | O32: 1 | P32: 1 | Q32: 3 | R32: 1 | S32: 0 | T32: 1 | U32: 1 | V32: 0 | W32: 2 | X32: 2 | Y32: – | Z32: 1 | AA32: 0 | AB32: 1 | AC32: 1 | AD32: 1 | AE32: 2 | AF32: 2 | AG32: 1 | AH32: 2 | AI32: 1 | AJ32: 1 | AK32: 1 | AL32: 3 | AM32: 0 | AN32: 2 | AO32: 2 | AP32: – | AQ32: 2 | AR32: 2 | AS32: 1 | AT32: 0 | AU32: 2 | AV32: – | AW32: – | AX32: 3 | AY32: – | AZ32: 3 | BA32: 1 | BB32: 2 | BC32: 2 | BD32: 2 | BE32: 2 | BF32: 0 | BG32: =IFERROR(AVERAGE(I32:Y32),"–") -> 1.25 | BH32: =IFERROR(AVERAGE(Z32:AM32),"–") -> 1.2142857 | BI32: =IFERROR(AVERAGE(AN32:AY32),"–") -> 1.75 | BJ32: =IFERROR(AVERAGE(AZ32:BA32),"–") -> 2 | BK32: =IFERROR(AVERAGE(BB32:BF32),"–") -> 1.6 | BL32: =IFERROR(AVERAGE(I32:BF32),"–") -> 1.4 | BM32: =COUNTIF(I32:BF32,0) -> 6
A33: Banane dessert | B33: BA_INT | C33: Banane : intensif de plaine | D33: 1258.2 | E33: AqYield / AqYieldNC | F33: plantation de 8 ans | G33: 0.82 | H33: 34 récoltes (max 1) ; 12 apports (max 4) | I33: 1 | J33: 2 | K33: 2 | L33: 1 | M33: 1 | N33: 1 | O33: 1 | P33: 1 | Q33: 3 | R33: 1 | S33: 0 | T33: 1 | U33: 1 | V33: 0 | W33: 2 | X33: 2 | Y33: – | Z33: 1 | AA33: 0 | AB33: 1 | AC33: 1 | AD33: 1 | AE33: 2 | AF33: 2 | AG33: 1 | AH33: 2 | AI33: 1 | AJ33: 1 | AK33: 1 | AL33: 3 | AM33: – | AN33: 2 | AO33: 2 | AP33: – | AQ33: 2 | AR33: 1 | AS33: 0 | AT33: 0 | AU33: 2 | AV33: 1 | AW33: 0 | AX33: 3 | AY33: – | AZ33: 3 | BA33: 1 | BB33: 2 | BC33: 2 | BD33: 2 | BE33: 2 | BF33: 0 | BG33: =IFERROR(AVERAGE(I33:Y33),"–") -> 1.25 | BH33: =IFERROR(AVERAGE(Z33:AM33),"–") -> 1.3076923 | BI33: =IFERROR(AVERAGE(AN33:AY33),"–") -> 1.3 | BJ33: =IFERROR(AVERAGE(AZ33:BA33),"–") -> 2 | BK33: =IFERROR(AVERAGE(BB33:BF33),"–") -> 1.6 | BL33: =IFERROR(AVERAGE(I33:BF33),"–") -> 1.3478261 | BM33: =COUNTIF(I33:BF33,0) -> 7
A34: Banane dessert | B34: BA_PER | C34: Banane : extensif d'altitude | D34: 288.7 | E34: AqYield / AqYieldNC | F34: plantation de 15 ans | G34: 0.84 | H34: 8.35 récoltes (max 1) ; 8 apports (max 4) | I34: 1 | J34: 2 | K34: 2 | L34: 1 | M34: 1 | N34: 1 | O34: 1 | P34: 1 | Q34: 3 | R34: 1 | S34: 0 | T34: 1 | U34: 1 | V34: 0 | W34: 2 | X34: 2 | Y34: – | Z34: 1 | AA34: 0 | AB34: 1 | AC34: 1 | AD34: 1 | AE34: 2 | AF34: 2 | AG34: 1 | AH34: 2 | AI34: 1 | AJ34: 1 | AK34: 1 | AL34: 3 | AM34: – | AN34: 2 | AO34: 2 | AP34: – | AQ34: 2 | AR34: 1 | AS34: 0 | AT34: 0 | AU34: 2 | AV34: 1 | AW34: 0 | AX34: 3 | AY34: – | AZ34: 3 | BA34: 1 | BB34: 2 | BC34: 2 | BD34: 2 | BE34: 2 | BF34: 0 | BG34: =IFERROR(AVERAGE(I34:Y34),"–") -> 1.25 | BH34: =IFERROR(AVERAGE(Z34:AM34),"–") -> 1.3076923 | BI34: =IFERROR(AVERAGE(AN34:AY34),"–") -> 1.3 | BJ34: =IFERROR(AVERAGE(AZ34:BA34),"–") -> 2 | BK34: =IFERROR(AVERAGE(BB34:BF34),"–") -> 1.6 | BL34: =IFERROR(AVERAGE(I34:BF34),"–") -> 1.3478261 | BM34: =COUNTIF(I34:BF34,0) -> 7
A35: Banane dessert | B35: BA_SINT | C35: Banane : intensif d'altitude | D35: 204.5 | E35: AqYield / AqYieldNC | F35: plantation de 11 ans | G35: 0.83 | H35: 17 récoltes (max 1) ; 8 apports (max 4) | I35: 1 | J35: 2 | K35: 2 | L35: 1 | M35: 1 | N35: 1 | O35: 1 | P35: 1 | Q35: 3 | R35: 1 | S35: 0 | T35: 1 | U35: 1 | V35: 0 | W35: 2 | X35: 2 | Y35: – | Z35: 1 | AA35: 0 | AB35: 1 | AC35: 1 | AD35: 1 | AE35: 1 | AF35: 2 | AG35: 1 | AH35: 2 | AI35: 1 | AJ35: 1 | AK35: 1 | AL35: 3 | AM35: – | AN35: 2 | AO35: 2 | AP35: – | AQ35: 2 | AR35: 1 | AS35: 0 | AT35: 0 | AU35: 2 | AV35: 1 | AW35: 0 | AX35: 3 | AY35: – | AZ35: 3 | BA35: 1 | BB35: 2 | BC35: 2 | BD35: 2 | BE35: 2 | BF35: 0 | BG35: =IFERROR(AVERAGE(I35:Y35),"–") -> 1.25 | BH35: =IFERROR(AVERAGE(Z35:AM35),"–") -> 1.2307692 | BI35: =IFERROR(AVERAGE(AN35:AY35),"–") -> 1.3 | BJ35: =IFERROR(AVERAGE(AZ35:BA35),"–") -> 2 | BK35: =IFERROR(AVERAGE(BB35:BF35),"–") -> 1.6 | BL35: =IFERROR(AVERAGE(I35:BF35),"–") -> 1.326087 | BM35: =COUNTIF(I35:BF35,0) -> 7
A36: Banane dessert | B36: BA_IRR | C36: Banane : irrigué | D36: 169.4 | E36: AqYield / AqYieldNC | F36: plantation de 11 ans | G36: 0.85 | H36: 17 récoltes (max 1) ; 8 apports (max 4) | I36: 1 | J36: 2 | K36: 2 | L36: 1 | M36: 1 | N36: 1 | O36: 1 | P36: 1 | Q36: 3 | R36: 1 | S36: 0 | T36: 1 | U36: 1 | V36: 0 | W36: 2 | X36: 2 | Y36: – | Z36: 1 | AA36: 0 | AB36: 1 | AC36: 1 | AD36: 1 | AE36: 2 | AF36: 2 | AG36: 1 | AH36: 2 | AI36: 1 | AJ36: 1 | AK36: 1 | AL36: 3 | AM36: – | AN36: 2 | AO36: 2 | AP36: 1 | AQ36: 2 | AR36: 1 | AS36: 0 | AT36: 0 | AU36: 2 | AV36: 2 | AW36: 0 | AX36: 3 | AY36: – | AZ36: 3 | BA36: 1 | BB36: 2 | BC36: 2 | BD36: 2 | BE36: 2 | BF36: 0 | BG36: =IFERROR(AVERAGE(I36:Y36),"–") -> 1.25 | BH36: =IFERROR(AVERAGE(Z36:AM36),"–") -> 1.3076923 | BI36: =IFERROR(AVERAGE(AN36:AY36),"–") -> 1.3636364 | BJ36: =IFERROR(AVERAGE(AZ36:BA36),"–") -> 2 | BK36: =IFERROR(AVERAGE(BB36:BF36),"–") -> 1.6 | BL36: =IFERROR(AVERAGE(I36:BF36),"–") -> 1.3617021 | BM36: =COUNTIF(I36:BF36,0) -> 7
A37: Plantain | B37: BC_BT | C37: Plantain, Basse-Terre | D37: 116.9 | E37: AqYield / AqYieldNC | F37: plantation de 2 ans | G37: 0.34 | H37: 4.5 apports (max 4) ; 36 désherbages (max 5) | I37: 1 | J37: 2 | K37: 2 | L37: 1 | M37: 1 | N37: 1 | O37: 1 | P37: 1 | Q37: 3 | R37: 1 | S37: 0 | T37: 1 | U37: 1 | V37: 0 | W37: 2 | X37: 2 | Y37: – | Z37: 1 | AA37: 0 | AB37: 1 | AC37: 2 | AD37: 1 | AE37: 2 | AF37: 2 | AG37: 1 | AH37: 2 | AI37: 1 | AJ37: 1 | AK37: 1 | AL37: 3 | AM37: – | AN37: 2 | AO37: 2 | AP37: – | AQ37: 2 | AR37: 2 | AS37: 0 | AT37: 0 | AU37: 2 | AV37: 1 | AW37: 0 | AX37: 3 | AY37: – | AZ37: 3 | BA37: 1 | BB37: 2 | BC37: 2 | BD37: 2 | BE37: 2 | BF37: 0 | BG37: =IFERROR(AVERAGE(I37:Y37),"–") -> 1.25 | BH37: =IFERROR(AVERAGE(Z37:AM37),"–") -> 1.3846154 | BI37: =IFERROR(AVERAGE(AN37:AY37),"–") -> 1.4 | BJ37: =IFERROR(AVERAGE(AZ37:BA37),"–") -> 2 | BK37: =IFERROR(AVERAGE(BB37:BF37),"–") -> 1.6 | BL37: =IFERROR(AVERAGE(I37:BF37),"–") -> 1.3913043 | BM37: =COUNTIF(I37:BF37,0) -> 7
A38: Plantain | B38: BC_GTMG | C38: Plantain, Grande-Terre et Marie-Galante | D38: 30.3 | E38: AqYield / AqYieldNC | F38: plantation de 2 ans | G38: 0.33 | H38: 4.5 apports (max 4) ; 36 désherbages (max 5) | I38: 1 | J38: 2 | K38: 2 | L38: 1 | M38: 1 | N38: 1 | O38: 1 | P38: 1 | Q38: 3 | R38: 1 | S38: 0 | T38: 1 | U38: 1 | V38: 0 | W38: 2 | X38: 2 | Y38: – | Z38: 1 | AA38: 0 | AB38: 1 | AC38: 2 | AD38: 1 | AE38: 2 | AF38: 2 | AG38: 1 | AH38: 2 | AI38: 1 | AJ38: 1 | AK38: 1 | AL38: 3 | AM38: – | AN38: 2 | AO38: 2 | AP38: 1 | AQ38: 2 | AR38: 2 | AS38: 0 | AT38: 0 | AU38: 2 | AV38: 2 | AW38: 0 | AX38: 3 | AY38: – | AZ38: 3 | BA38: 1 | BB38: 2 | BC38: 2 | BD38: 2 | BE38: 2 | BF38: 0 | BG38: =IFERROR(AVERAGE(I38:Y38),"–") -> 1.25 | BH38: =IFERROR(AVERAGE(Z38:AM38),"–") -> 1.3846154 | BI38: =IFERROR(AVERAGE(AN38:AY38),"–") -> 1.4545455 | BJ38: =IFERROR(AVERAGE(AZ38:BA38),"–") -> 2 | BK38: =IFERROR(AVERAGE(BB38:BF38),"–") -> 1.6 | BL38: =IFERROR(AVERAGE(I38:BF38),"–") -> 1.4042553 | BM38: =COUNTIF(I38:BF38,0) -> 7
A39: Prairies | B39: PN_PIQ | C39: Prairie naturelle, élevage au piquet | D39: 6109.4 | E39: HerbSim / HerbSimNC | F39: annuelle | G39: 1 | I39: – | J39: – | K39: – | L39: – | M39: – | N39: – | O39: – | P39: – | Q39: – | R39: – | S39: – | T39: – | U39: – | V39: – | W39: – | X39: – | Y39: 0 | Z39: – | AA39: – | AB39: – | AC39: – | AD39: – | AE39: – | AF39: – | AG39: – | AH39: – | AI39: – | AJ39: – | AK39: – | AL39: – | AM39: – | AN39: 2 | AO39: 2 | AP39: – | AQ39: 0 | AR39: 1 | AS39: 0 | AT39: 0 | AU39: – | AV39: – | AW39: – | AX39: – | AY39: 0 | AZ39: – | BA39: – | BB39: 2 | BC39: 2 | BD39: 2 | BE39: 2 | BF39: 0 | BG39: =IFERROR(AVERAGE(I39:Y39),"–") -> 0 | BH39: =IFERROR(AVERAGE(Z39:AM39),"–") -> – | BI39: =IFERROR(AVERAGE(AN39:AY39),"–") -> 0.71428571 | BJ39: =IFERROR(AVERAGE(AZ39:BA39),"–") -> – | BK39: =IFERROR(AVERAGE(BB39:BF39),"–") -> 1.6 | BL39: =IFERROR(AVERAGE(I39:BF39),"–") -> 1 | BM39: =COUNTIF(I39:BF39,0) -> 6
A40: Prairies | B40: PN_TOUR | C40: Prairie naturelle, pâturage tournant | D40: 0 | E40: HerbSim / HerbSimNC | F40: annuelle | G40: 0.88 | I40: – | J40: – | K40: – | L40: – | M40: – | N40: – | O40: – | P40: – | Q40: – | R40: – | S40: – | T40: – | U40: – | V40: – | W40: – | X40: – | Y40: 0 | Z40: – | AA40: – | AB40: – | AC40: – | AD40: – | AE40: – | AF40: – | AG40: – | AH40: – | AI40: – | AJ40: – | AK40: – | AL40: – | AM40: – | AN40: 2 | AO40: 2 | AP40: – | AQ40: 1 | AR40: 1 | AS40: 0 | AT40: 0 | AU40: – | AV40: – | AW40: – | AX40: 3 | AY40: 0 | AZ40: 3 | BA40: 0 | BB40: 2 | BC40: 2 | BD40: 2 | BE40: 2 | BF40: 0 | BG40: =IFERROR(AVERAGE(I40:Y40),"–") -> 0 | BH40: =IFERROR(AVERAGE(Z40:AM40),"–") -> – | BI40: =IFERROR(AVERAGE(AN40:AY40),"–") -> 1.125 | BJ40: =IFERROR(AVERAGE(AZ40:BA40),"–") -> 1.5 | BK40: =IFERROR(AVERAGE(BB40:BF40),"–") -> 1.6 | BL40: =IFERROR(AVERAGE(I40:BF40),"–") -> 1.25 | BM40: =COUNTIF(I40:BF40,0) -> 6
...

Sheet Paramètres
A1: Dictionnaire des paramètres de la feuille Cultures
A2: Une ligne par colonne notée. Les décomptes renvoient à la feuille Cultures ; les pistes de sources sont à valider.
A4: Bloc | B4: Paramètre MAELIA | C4: Signification | D4: Unité | E4: Nécessité | F4: Ce que MOSAICA a | G4: Règle de notation | H4: Pistes de sources | I4: Lien | J4: Moyenne | K4: Moyenne pondérée surface | L4: Cultures à 0 | M4: à 1 | N4: à 2 | O4: à 3 | P4: sans objet | Q4: Surface à 0 (ha) | R4: Surface à 0 ou 1 (ha)
A5: Espèce : eau, phéno | B5: RENDEMENT_OPTIMAL | C5: Rendement potentiel local, que le modèle réduit selon les stress hydrique et azoté. À adapter au terrain (obligatoire). | D5: t/ha | E5: obligatoire | F5: Aucune : Rdt_Cult est un rendement moyen atteint, pas un potentiel. | G5: 1 si des essais ou références donnent un potentiel pour la plante, 0 sinon (mélanges, prairie). | H5: Essais INRAE/CIRAD, CTCS (canne), IT2 (banane, diversification), Agreste (meilleures années). La grille d'enquête ITK le demande par culture et par type de sol. En 1.4.31 : parametres/rendements_optimaux.csv. | I5: https://daaf.guadeloupe.agriculture.gouv.fr/ | J5: =IFERROR(AVERAGE(Cultures!$I$5:$I$79),"–") -> 0.56944444 | K5: =IFERROR(SUMPRODUCT(Cultures!$D$5:$D$79,Cultures!$I$5:$I$79)/SUMIF(Cultures!$I$5:$I$79,">=0",Cultures!$D$5:$D$79),"–") -> 0.91702662 | L5: =COUNTIF(Cultures!$I$5:$I$79,0) -> 31 | M5: =COUNTIF(Cultures!$I$5:$I$79,1) -> 41 | N5: =COUNTIF(Cultures!$I$5:$I$79,2) -> 0 | O5: =COUNTIF(Cultures!$I$5:$I$79,3) -> 0 | P5: =COUNTIF(Cultures!$I$5:$I$79,"–") -> 3 | Q5: =SUMIF(Cultures!$I$5:$I$79,0,Cultures!$D$5:$D$79) -> 1397.86 | R5: =SUMIF(Cultures!$I$5:$I$79,"<=1",Cultures!$D$5:$D$79) -> 16847.09
A6: Espèce : eau, phéno | B6: RENDEMENT_MOYEN | C6: Rendement moyen, sert à la validation. | D6: t/ha | E6: optionnel | F6: Rdt_Cult_CF_<scénario>. | G6: 2 : présent, mais 1 à 4 fois le rendement du territoire (vigilance C.1). | H6: Agreste (statistique agricole annuelle), CTCS, LPG. | I6: https://daaf.guadeloupe.agriculture.gouv.fr/ | J6: =IFERROR(AVERAGE(Cultures!$J$5:$J$79),"–") -> 2 | K6: =IFERROR(SUMPRODUCT(Cultures!$D$5:$D$79,Cultures!$J$5:$J$79)/SUMIF(Cultures!$J$5:$J$79,">=0",Cultures!$D$5:$D$79),"–") -> 2 | L6: =COUNTIF(Cultures!$J$5:$J$79,0) -> 0 | M6: =COUNTIF(Cultures!$J$5:$J$79,1) -> 0 | N6: =COUNTIF(Cultures!$J$5:$J$79,2) -> 72 | O6: =COUNTIF(Cultures!$J$5:$J$79,3) -> 0 | P6: =COUNTIF(Cultures!$J$5:$J$79,"–") -> 3 | Q6: =SUMIF(Cultures!$J$5:$J$79,0,Cultures!$D$5:$D$79) -> 0 | R6: =SUMIF(Cultures!$J$5:$J$79,"<=1",Cultures!$D$5:$D$79) -> 0
A7: Espèce : eau, phéno | B7: RENDEMENT_MIN | C7: Rendement minimum, sert à la validation. | D7: t/ha | E7: optionnel | F7: Var_Rdt_Cult (une variance, pas un minimum). | G7: 2 si une variance existe (minimum à en déduire), 1 sinon. | H7: Séries Agreste par culture. | I7: https://daaf.guadeloupe.agriculture.gouv.fr/ | J7: =IFERROR(AVERAGE(Cultures!$K$5:$K$79),"–") -> 1.9583333 | K7: =IFERROR(SUMPRODUCT(Cultures!$D$5:$D$79,Cultures!$K$5:$K$79)/SUMIF(Cultures!$K$5:$K$79,">=0",Cultures!$D$5:$D$79),"–") -> 1.8702393 | L7: =COUNTIF(Cultures!$K$5:$K$79,0) -> 0 | M7: =COUNTIF(Cultures!$K$5:$K$79,1) -> 3 | N7: =COUNTIF(Cultures!$K$5:$K$79,2) -> 69 | O7: =COUNTIF(Cultures!$K$5:$K$79,3) -> 0 | P7: =COUNTIF(Cultures!$K$5:$K$79,"–") -> 3 | Q7: =SUMIF(Cultures!$K$5:$K$79,0,Cultures!$D$5:$D$79) -> 0 | R7: =SUMIF(Cultures!$K$5:$K$79,"<=1",Cultures!$D$5:$D$79) -> 2186.09
